<?xml version="1.0" encoding="utf-8"?><robot name="RehabConcept"><joint name="BaseLink_joint" type="fixed"><origin rpy="0 -0 0" xyz="0 0 0"/><parent link="BaseLink"/><child link="BaseLink_link"/><axis xyz="0 0 1"/><calibration falling="0.0" reference_position="0.0" rising="0.0"/><dynamics damping="1.0"/><limit effort="100.0" lower="1.0" upper="1.0" velocity="1.0"/></joint><joint name="Prism1Base_joint" type="fixed"><origin rpy="0 -0 0" xyz="0.36654898524284363 0.3124290108680725 0.0005189999938011169"/><parent link="BaseLink_link"/><child link="Prism1Base_link"/><axis xyz="0 0 1"/><calibration falling="0.0" reference_position="0.0" rising="0.0"/><dynamics damping="1.0"/><limit effort="100.0" lower="1.0" upper="1.0" velocity="1.0"/></joint><joint name="Prism1MidSlider_joint" type="prismatic"><origin rpy="0 -0 0" xyz="0 0 0.012490999884903431"/><parent link="Prism1Base_link"/><child link="Prism1MidSlider_link"/><axis xyz="0 1 0"/><calibration falling="0.0" reference_position="0.0" rising="0.0"/><dynamics damping="1.0"/><limit effort="100.0" lower="-90.0" upper="90.0" velocity="1.0"/></joint><joint name="Prism1Connector_joint" type="prismatic"><origin rpy="0 -0 0" xyz="-0.0011729896068572998 0 0"/><parent link="Prism1MidSlider_link"/><child link="Prism1Connector_link"/><axis xyz="1 0 0"/><calibration falling="0.0" reference_position="0.0" rising="0.0"/><dynamics damping="1.0"/><limit effort="100.0" lower="-90.0" upper="90.0" velocity="1.0"/></joint><joint name="Act1_joint" type="fixed"><origin rpy="0 -0 0" xyz="0 -0.06608504056930542 0"/><parent link="Prism1Connector_link"/><child link="Act1_link"/><axis xyz="0 0 1"/><calibration falling="0.0" reference_position="0.0" rising="0.0"/><dynamics damping="1.0"/><limit effort="100.0" lower="1.0" upper="1.0" velocity="1.0"/></joint><joint name="ShoulderLink1_joint" type="revolute"><origin rpy="0 -0 0" xyz="0 -0.05040693283081055 0"/><parent link="Act1_link"/><child link="ShoulderLink1_link"/><axis xyz="0 0 1"/><calibration falling="0.0" reference_position="0.0" rising="0.0"/><dynamics damping="1.0"/><limit effort="100.0" lower="-1.5707963267948966" upper="1.5707963267948966" velocity="1.0"/></joint><link name="BaseLink"/><link name="BaseLink_link"><inertial><origin rpy="0 0 0" xyz="0 0 0"/><mass value="1.0"/><inertia ixx="1.0" ixy="0.0" ixz="0.0" iyy="1.0" iyz="0.0" izz="1.0"/></inertial><visual><origin rpy="-1.5707963705062866 -0 0" xyz="0 0 0"/><geometry><mesh filename="file:///home/tomislav/ros/catkin_tutor/src/rehab/urdf/RehabConcept/meshes/VIS_BaseLink.dae" scale="1 1 1"/></geometry></visual></link><link name="Prism1Base_link"><inertial><origin rpy="0 0 0" xyz="0 0 0"/><mass value="1.0"/><inertia ixx="1.0" ixy="0.0" ixz="0.0" iyy="1.0" iyz="0.0" izz="1.0"/></inertial><visual><origin rpy="-1.5707963705062866 -0 0" xyz="0 -2.9802322387695312e-08 3.3527612686157227e-07"/><geometry><mesh filename="file:///home/tomislav/ros/catkin_tutor/src/rehab/urdf/RehabConcept/meshes/VIS_Prism1Base.dae" scale="1 1 1"/></geometry></visual></link><link name="Prism1MidSlider_link"><inertial><origin rpy="0 0 0" xyz="0 0 0"/><mass value="1.0"/><inertia ixx="1.0" ixy="0.0" ixz="0.0" iyy="1.0" iyz="0.0" izz="1.0"/></inertial><visual><origin rpy="-1.5707963705062866 -0 0" xyz="0 -2.9802322387695312e-08 6.370246410369873e-07"/><geometry><mesh filename="file:///home/tomislav/ros/catkin_tutor/src/rehab/urdf/RehabConcept/meshes/VIS_Prism1MidSlider.dae" scale="1 1 1"/></geometry></visual></link><link name="Prism1Connector_link"><inertial><origin rpy="0 0 0" xyz="0 0 0"/><mass value="1.0"/><inertia ixx="1.0" ixy="0.0" ixz="0.0" iyy="1.0" iyz="0.0" izz="1.0"/></inertial><visual><origin rpy="-1.5707963705062866 -0 0" xyz="-4.507601261138916e-07 -2.9802322387695312e-08 6.370246410369873e-07"/><geometry><mesh filename="file:///home/tomislav/ros/catkin_tutor/src/rehab/urdf/RehabConcept/meshes/VIS_Prism1Connector.dae" scale="1 1 1"/></geometry></visual></link><link name="Act1_link"><inertial><origin rpy="0 0 0" xyz="0 0 0"/><mass value="1.0"/><inertia ixx="1.0" ixy="0.0" ixz="0.0" iyy="1.0" iyz="0.0" izz="1.0"/></inertial><visual><origin rpy="-1.5707963705062866 -0 0" xyz="-4.507601261138916e-07 1.4901161193847656e-08 6.370246410369873e-07"/><geometry><mesh filename="file:///home/tomislav/ros/catkin_tutor/src/rehab/urdf/RehabConcept/meshes/VIS_Act1.dae" scale="1 1 1"/></geometry></visual></link><link name="ShoulderLink1_link"><inertial><origin rpy="0 0 0" xyz="0 0 0"/><mass value="1.0"/><inertia ixx="1.0" ixy="0.0" ixz="0.0" iyy="1.0" iyz="0.0" izz="1.0"/></inertial><visual><origin rpy="-1.5707963705062866 -0 0" xyz="-4.5262277126312256e-07 3.5762786865234375e-07 6.370246410369873e-07"/><geometry><mesh filename="file:///home/tomislav/ros/catkin_tutor/src/rehab/urdf/RehabConcept/meshes/VIS_ShoulderLink1.dae" scale="1 1 1"/></geometry></visual></link><gazebo><plugin filename="libgeneric_controller_plugin.so" name="generic_controller"><controller joint_name="BaseLink_joint"><type>position</type><pid>100 1 1</pid></controller><controller joint_name="Prism1Base_joint"><type>position</type><pid>100 1 1</pid></controller><controller joint_name="Prism1MidSlider_joint"><type>position</type><pid>100 1 1</pid></controller><controller joint_name="Prism1Connector_joint"><type>position</type><pid>100 1 1</pid></controller><controller joint_name="Act1_joint"><type>position</type><pid>100 1 1</pid></controller><controller joint_name="ShoulderLink1_joint"><type>position</type><pid>100 1 1</pid></controller></plugin></gazebo></robot>