<?xml version="1.0" ?>
<sdf version="1.6">
	<model name="ForearmRehabSimplified">
		<pose>0.0 0.0 0.0 0.0 0.0 0.0</pose>
		<link name="DummyBase">
			<gravity>false</gravity>
			<self_collide>false</self_collide>
			<pose>0.0 0.0 0.0 0.0 -0.0 0.0</pose>
			<inertial>
				<mass>1.0</mass>
				<inertia>
					<ixx>1.0</ixx>
					<ixy>0.0</ixy>
					<ixz>0.0</ixz>
					<iyy>1.0</iyy>
					<iyz>0.0</iyz>
					<izz>1.0</izz>
				</inertia>
				<pose>0 0 0 0 0 0</pose>
			</inertial>
		</link>
		<link name="BaseLink">
			<gravity>true</gravity>
			<self_collide>true</self_collide>
			<pose>0.0 0.0 0.0 0.0 -0.0 0.0</pose>
			<inertial>
				<mass>1.0</mass>
				<inertia>
					<ixx>1.0</ixx>
					<ixy>0.0</ixy>
					<ixz>0.0</ixz>
					<iyy>1.0</iyy>
					<iyz>0.0</iyz>
					<izz>1.0</izz>
				</inertia>
				<pose>0 0 0 0 0 0</pose>
			</inertial>
			<visual name="VIS_BaseLink">
				<pose>0.0 0.0 0.0 0.0 -0.0 0.0</pose>
				<geometry>
					<mesh>
						<uri>model://ForearmRehabSimplified/meshes/visual/VIS_BaseLink.dae</uri>
						<scale>1.0 1.0 1.0</scale>
					</mesh>
				</geometry>
			</visual>
		</link>
		<link name="ElbowWristLink">
			<gravity>true</gravity>
			<self_collide>true</self_collide>
			<pose>0.09929899871349335 -0.03790295124053955 0.13185299932956696 0.0 -0.0 0.0</pose>
			<inertial>
				<mass>1.0</mass>
				<inertia>
					<ixx>1.0</ixx>
					<ixy>0.0</ixy>
					<ixz>0.0</ixz>
					<iyy>1.0</iyy>
					<iyz>0.0</iyz>
					<izz>1.0</izz>
				</inertia>
				<pose>0 0 0 0 0 0</pose>
			</inertial>
			<visual name="VIS_ElbowWristLink">
				<pose>4.3213367462158203e-07 3.5762786865234375e-07 -1.4901161193847656e-08 0.0 -0.0 0.0</pose>
				<geometry>
					<mesh>
						<uri>model://ForearmRehabSimplified/meshes/visual/VIS_ElbowWristLink.dae</uri>
						<scale>1.0 1.0 1.0</scale>
					</mesh>
				</geometry>
			</visual>
		</link>
		<link name="Prism1MidSlider">
			<gravity>true</gravity>
			<self_collide>true</self_collide>
			<pose>0.2650749981403351 -0.009253978729248047 0.06786900013685226 0.0 -0.0 0.0</pose>
			<inertial>
				<mass>1.0</mass>
				<inertia>
					<ixx>1.0</ixx>
					<ixy>0.0</ixy>
					<ixz>0.0</ixz>
					<iyy>1.0</iyy>
					<iyz>0.0</iyz>
					<izz>1.0</izz>
				</inertia>
				<pose>0 0 0 0 0 0</pose>
			</inertial>
			<visual name="VIS_Prism1MidSlider">
				<pose>-1.1920928955078125e-07 4.470348358154297e-07 6.705522537231445e-08 2.117582368135751e-22 -0.0 3.552713678800501e-15</pose>
				<geometry>
					<mesh>
						<uri>model://ForearmRehabSimplified/meshes/visual/VIS_Prism1MidSlider.dae</uri>
						<scale>1.0 1.0 1.0</scale>
					</mesh>
				</geometry>
			</visual>
		</link>
		<link name="WristLink1">
			<gravity>true</gravity>
			<self_collide>true</self_collide>
			<pose>0.2647170126438141 -0.009253978729248047 0.16250300407409668 0.0 -0.0 0.0</pose>
			<inertial>
				<mass>1.0</mass>
				<inertia>
					<ixx>1.0</ixx>
					<ixy>0.0</ixy>
					<ixz>0.0</ixz>
					<iyy>1.0</iyy>
					<iyz>0.0</iyz>
					<izz>1.0</izz>
				</inertia>
				<pose>0 0 0 0 0 0</pose>
			</inertial>
			<visual name="VIS_WristLink1">
				<pose>-2.9802322387695312e-08 4.3213367462158203e-07 -4.76837158203125e-07 2.117582368135751e-22 -0.0 3.552713678800501e-15</pose>
				<geometry>
					<mesh>
						<uri>model://ForearmRehabSimplified/meshes/visual/VIS_WristLink1.dae</uri>
						<scale>1.0 1.0 1.0</scale>
					</mesh>
				</geometry>
			</visual>
		</link>
		<link name="WristLink2">
			<gravity>true</gravity>
			<self_collide>true</self_collide>
			<pose>0.36778801679611206 -0.016865015029907227 0.10667700320482254 0.0 -0.0 0.0</pose>
			<inertial>
				<mass>1.0</mass>
				<inertia>
					<ixx>1.0</ixx>
					<ixy>0.0</ixy>
					<ixz>0.0</ixz>
					<iyy>1.0</iyy>
					<iyz>0.0</iyz>
					<izz>1.0</izz>
				</inertia>
				<pose>0 0 0 0 0 0</pose>
			</inertial>
			<visual name="VIS_WristLink2">
				<pose>-2.9802322387695312e-08 2.682209014892578e-07 5.21540641784668e-08 2.117582368135751e-22 -0.0 3.552713678800501e-15</pose>
				<geometry>
					<mesh>
						<uri>model://ForearmRehabSimplified/meshes/visual/VIS_WristLink2.dae</uri>
						<scale>1.0 1.0 1.0</scale>
					</mesh>
				</geometry>
			</visual>
		</link>
		<link name="HandLink">
			<gravity>true</gravity>
			<self_collide>true</self_collide>
			<pose>0.3686010241508484 -0.08284497261047363 0.1690009981393814 0.0 -0.0 0.0</pose>
			<inertial>
				<mass>1.0</mass>
				<inertia>
					<ixx>1.0</ixx>
					<ixy>0.0</ixy>
					<ixz>0.0</ixz>
					<iyy>1.0</iyy>
					<iyz>0.0</iyz>
					<izz>1.0</izz>
				</inertia>
				<pose>0 0 0 0 0 0</pose>
			</inertial>
			<visual name="VIS_HandLink">
				<pose>2.9802322387695312e-08 -2.682209014892578e-07 1.6391277313232422e-07 -1.2621775988168958e-29 -0.0 2.117582368135751e-22</pose>
				<geometry>
					<mesh>
						<uri>model://ForearmRehabSimplified/meshes/visual/VIS_HandLink.dae</uri>
						<scale>1.1748089790344238 1.0 1.6057640314102173</scale>
					</mesh>
				</geometry>
			</visual>
		</link>
		<link name="Prism2MidSlider">
			<gravity>true</gravity>
			<self_collide>true</self_collide>
			<pose>0.45214101672172546 -0.08284497261047363 0.1690009981393814 0.0 -0.0 0.0</pose>
			<inertial>
				<mass>1.0</mass>
				<inertia>
					<ixx>1.0</ixx>
					<ixy>0.0</ixy>
					<ixz>0.0</ixz>
					<iyy>1.0</iyy>
					<iyz>0.0</iyz>
					<izz>1.0</izz>
				</inertia>
				<pose>0 0 0 0 0 0</pose>
			</inertial>
			<visual name="VIS_Prism2MidSlider">
				<pose>3.5762786865234375e-07 -2.682209014892578e-07 -7.450580596923828e-08 0.0 -0.0 0.0</pose>
				<geometry>
					<mesh>
						<uri>model://ForearmRehabSimplified/meshes/visual/VIS_Prism2MidSlider.dae</uri>
						<scale>1.0 1.0 1.0</scale>
					</mesh>
				</geometry>
			</visual>
		</link>
		<link name="HandInterface">
			<gravity>true</gravity>
			<self_collide>true</self_collide>
			<pose>0.452210009098053 0.007309019565582275 0.15981200337409973 0.0 -0.0 0.0</pose>
			<inertial>
				<mass>1.0</mass>
				<inertia>
					<ixx>1.0</ixx>
					<ixy>0.0</ixy>
					<ixz>0.0</ixz>
					<iyy>1.0</iyy>
					<iyz>0.0</iyz>
					<izz>1.0</izz>
				</inertia>
				<pose>0 0 0 0 0 0</pose>
			</inertial>
			<visual name="VIS_HandInterface">
				<pose>-8.940696716308594e-08 -6.92903995513916e-07 -5.364418029785156e-07 0.0 -0.0 0.0</pose>
				<geometry>
					<mesh>
						<uri>model://ForearmRehabSimplified/meshes/visual/VIS_HandInterface.dae</uri>
						<scale>1.0 1.0 1.0</scale>
					</mesh>
				</geometry>
			</visual>
		</link>
		<joint name="BaseLink_joint" type="fixed">
			<parent>DummyBase</parent>
			<child>BaseLink</child>
			<axis>
				<xyz>0.0 0.0 1.0</xyz>
				<dynamics>
					<damping>0.0</damping>
					<friction>0.0</friction>
					<spring_reference>0.0</spring_reference>
					<spring_stiffness>0.0</spring_stiffness>
				</dynamics>
			</axis>
			<physics>
				<ode>
					<cfm_damping>false</cfm_damping>
					<implicit_spring_damper>false</implicit_spring_damper>
					<cfm>0.0</cfm>
					<erp>0.20000000298023224</erp>
				</ode>
			</physics>
		</joint>
		<joint name="ElbowWristLink_joint" type="revolute">
			<parent>BaseLink</parent>
			<child>ElbowWristLink</child>
			<axis>
				<xyz>0.0 1.0 0.0</xyz>
				<dynamics>
					<damping>0.0</damping>
					<friction>0.0</friction>
					<spring_reference>0.0</spring_reference>
					<spring_stiffness>0.0</spring_stiffness>
				</dynamics>
				<limit>
					<lower>-1.5707963267948966</lower>
					<upper>0.0</upper>
				</limit>
			</axis>
			<physics>
				<ode>
					<cfm_damping>false</cfm_damping>
					<implicit_spring_damper>false</implicit_spring_damper>
					<cfm>0.0</cfm>
					<erp>0.20000000298023224</erp>
				</ode>
			</physics>
		</joint>
		<joint name="Prism1MidSlider_joint" type="revolute">
			<parent>ElbowWristLink</parent>
			<child>Prism1MidSlider</child>
			<axis>
				<xyz>1.0 0.0 0.0</xyz>
				<dynamics>
					<damping>0.0</damping>
					<friction>0.0</friction>
					<spring_reference>0.0</spring_reference>
					<spring_stiffness>0.0</spring_stiffness>
				</dynamics>
				<limit>
					<lower>-1.7453292079036042e-06</lower>
					<upper>1.7453292079036042e-06</upper>
				</limit>
			</axis>
			<physics>
				<ode>
					<cfm_damping>false</cfm_damping>
					<implicit_spring_damper>false</implicit_spring_damper>
					<cfm>0.0</cfm>
					<erp>0.20000000298023224</erp>
				</ode>
			</physics>
		</joint>
		<joint name="WristLink1_joint" type="revolute">
			<parent>Prism1MidSlider</parent>
			<child>WristLink1</child>
			<axis>
				<xyz>1.0 0.0 0.0</xyz>
				<dynamics>
					<damping>0.0</damping>
					<friction>0.0</friction>
					<spring_reference>0.0</spring_reference>
					<spring_stiffness>0.0</spring_stiffness>
				</dynamics>
				<limit>
					<lower>-1.9198621771937625</lower>
					<upper>1.9198621771937625</upper>
				</limit>
			</axis>
			<physics>
				<ode>
					<cfm_damping>false</cfm_damping>
					<implicit_spring_damper>false</implicit_spring_damper>
					<cfm>0.0</cfm>
					<erp>0.20000000298023224</erp>
				</ode>
			</physics>
		</joint>
		<joint name="WristLink2_joint" type="revolute">
			<parent>WristLink1</parent>
			<child>WristLink2</child>
			<axis>
				<xyz>0.0 0.0 1.0</xyz>
				<dynamics>
					<damping>0.0</damping>
					<friction>0.0</friction>
					<spring_reference>0.0</spring_reference>
					<spring_stiffness>0.0</spring_stiffness>
				</dynamics>
				<limit>
					<lower>-0.9599310885968813</lower>
					<upper>2.0943951023931953</upper>
				</limit>
			</axis>
			<physics>
				<ode>
					<cfm_damping>false</cfm_damping>
					<implicit_spring_damper>false</implicit_spring_damper>
					<cfm>0.0</cfm>
					<erp>0.20000000298023224</erp>
				</ode>
			</physics>
		</joint>
		<joint name="HandLink_joint" type="revolute">
			<parent>WristLink2</parent>
			<child>HandLink</child>
			<axis>
				<xyz>0.0 1.0 0.0</xyz>
				<dynamics>
					<damping>0.0</damping>
					<friction>0.0</friction>
					<spring_reference>0.0</spring_reference>
					<spring_stiffness>0.0</spring_stiffness>
				</dynamics>
				<limit>
					<lower>-1.0471975511965976</lower>
					<upper>0.5235987755982988</upper>
				</limit>
			</axis>
			<physics>
				<ode>
					<cfm_damping>false</cfm_damping>
					<implicit_spring_damper>false</implicit_spring_damper>
					<cfm>0.0</cfm>
					<erp>0.20000000298023224</erp>
				</ode>
			</physics>
		</joint>
		<joint name="Prism2MidSlider_joint" type="revolute">
			<parent>HandLink</parent>
			<child>Prism2MidSlider</child>
			<axis>
				<xyz>1.0 0.0 0.0</xyz>
				<dynamics>
					<damping>0.0</damping>
					<friction>0.0</friction>
					<spring_reference>0.0</spring_reference>
					<spring_stiffness>0.0</spring_stiffness>
				</dynamics>
				<limit>
					<lower>-1.7453292079036042e-06</lower>
					<upper>1.7453292079036042e-06</upper>
				</limit>
			</axis>
			<physics>
				<ode>
					<cfm_damping>false</cfm_damping>
					<implicit_spring_damper>false</implicit_spring_damper>
					<cfm>0.0</cfm>
					<erp>0.20000000298023224</erp>
				</ode>
			</physics>
		</joint>
		<joint name="HandInterface_joint" type="fixed">
			<parent>Prism2MidSlider</parent>
			<child>HandInterface</child>
			<axis>
				<xyz>0.0 0.0 1.0</xyz>
				<dynamics>
					<damping>0.0</damping>
					<friction>0.0</friction>
					<spring_reference>0.0</spring_reference>
					<spring_stiffness>0.0</spring_stiffness>
				</dynamics>
			</axis>
			<physics>
				<ode>
					<cfm_damping>false</cfm_damping>
					<implicit_spring_damper>false</implicit_spring_damper>
					<cfm>0.0</cfm>
					<erp>0.20000000298023224</erp>
				</ode>
			</physics>
		</joint>
	</model>
</sdf>
