<?xml version="1.0" ?>
<robot name="ForearmRehab">
  <joint name="ElbowWristLink_joint" type="revolute">
    <parent link="BaseLink"/>
    <child link="ElbowWristLink"/>
    <origin xyz="0.09929 -0.0379   0.13185" rpy="0 0 0"/>
    <axis xyz="0 1 0"/>
    <limit lower="-1.5707963267948966" upper="0.0" effort="0.0" velocity="0.0"/>
  </joint>
  <joint name="Act1_joint" type="fixed">
    <parent link="ElbowWristLink"/>
    <child link="Act1"/>
    <origin xyz="0      -0.01441  0" rpy="0 0 0"/>
    <axis xyz="0 0 1"/>
    <limit lower="0" upper="0" effort="0" velocity="0"/>
  </joint>
  <joint name="Prism1Base_joint" type="fixed">
    <parent link="ElbowWristLink"/>
    <child link="Prism1Base"/>
    <origin xyz="0.16407  0.02864 -0.06398" rpy="0 0 0"/>
    <axis xyz="0 0 1"/>
    <limit lower="0" upper="0" effort="0" velocity="0"/>
  </joint>
  <joint name="Prism1MidSlider_joint" type="prismatic">
    <parent link="Prism1Base"/>
    <child link="Prism1MidSlider"/>
    <origin xyz="0.00169 0      0" rpy="0 0 0"/>
    <axis xyz="1 0 0"/>
    <limit lower="-0.00800000037997961" upper="0.00800000037997961" effort="0.0" velocity="0.0"/>
  </joint>
  <joint name="WristSlider1_joint" type="fixed">
    <parent link="Prism1MidSlider"/>
    <child link="WristSlider1"/>
    <origin xyz="0.0178  0      0.09463" rpy="0 0 0"/>
    <axis xyz="0 0 1"/>
    <limit lower="0" upper="0" effort="0" velocity="0"/>
  </joint>
  <joint name="WristSlider2_joint" type="fixed">
    <parent link="Prism1MidSlider"/>
    <child link="WristSlider2"/>
    <origin xyz="-0.01851  0       0.09463" rpy="0 0 0"/>
    <axis xyz="0 0 1"/>
    <limit lower="0" upper="0" effort="0" velocity="0"/>
  </joint>
  <joint name="Act2_joint" type="fixed">
    <parent link="WristSlider2"/>
    <child link="Act2"/>
    <origin xyz="0.00258  0      -0.05695" rpy="0 0 0"/>
    <axis xyz="0 0 1"/>
    <limit lower="0" upper="0" effort="0" velocity="0"/>
  </joint>
  <joint name="WristLink1_joint" type="revolute">
    <parent link="WristSlider2"/>
    <child link="WristLink1"/>
    <origin xyz="0.01816 0      0" rpy="0 0 0"/>
    <axis xyz="1 0 0"/>
    <limit lower="-1.9198621771937625" upper="1.9198621771937625" effort="0.0" velocity="0.0"/>
  </joint>
  <joint name="WristRail1_joint" type="fixed">
    <parent link="WristLink1"/>
    <child link="WristRail1"/>
    <origin xyz="-0.01548  0       0" rpy="0 0 0"/>
    <axis xyz="0 0 1"/>
    <limit lower="0" upper="0" effort="0" velocity="0"/>
  </joint>
  <joint name="WristRail2_joint" type="fixed">
    <parent link="WristLink1"/>
    <child link="WristRail2"/>
    <origin xyz="0.01548 0      0" rpy="0 0 0"/>
    <axis xyz="0 0 1"/>
    <limit lower="0" upper="0" effort="0" velocity="0"/>
  </joint>
  <joint name="ForearmInterface_joint" type="fixed">
    <parent link="WristLink1"/>
    <child link="ForearmInterface"/>
    <origin xyz="0 0 0" rpy="0 0 0"/>
    <axis xyz="0 0 1"/>
    <limit lower="0" upper="0" effort="0" velocity="0"/>
  </joint>
  <joint name="Wristlink2_joint" type="revolute">
    <parent link="WristLink1"/>
    <child link="Wristlink2"/>
    <origin xyz="0.10307 -0.00761 -0.05582" rpy="0 0 0"/>
    <axis xyz="0 0 1"/>
    <limit lower="-0.9599310885968813" upper="2.0943951023931953" effort="0.0" velocity="0.0"/>
  </joint>
  <joint name="ElasticHingePart1_joint" type="revolute">
    <parent link="Wristlink2"/>
    <child link="ElasticHingePart1"/>
    <origin xyz="0.00081 -0.08572  0.06232" rpy="0 0 0"/>
    <axis xyz="0 1 0"/>
    <limit lower="-1.0471975511965976" upper="0.5235987755982988" effort="0.0" velocity="0.0"/>
  </joint>
  <joint name="Act4_joint" type="fixed">
    <parent link="ElasticHingePart1"/>
    <child link="Act4"/>
    <origin xyz="0      -0.01129  0" rpy="0 0 0"/>
    <axis xyz="0 0 1"/>
    <limit lower="0" upper="0" effort="0" velocity="0"/>
  </joint>
  <joint name="ElasticHingePart2_joint" type="revolute">
    <parent link="ElasticHingePart1"/>
    <child link="ElasticHingePart2"/>
    <origin xyz="0.03731 0      0" rpy="0 0 0"/>
    <axis xyz="0 1 0"/>
    <limit lower="-0.08726646259971647" upper="0.08726646259971647" effort="0.0" velocity="0.0"/>
  </joint>
  <joint name="Prism2Base_joint" type="fixed">
    <parent link="ElasticHingePart2"/>
    <child link="Prism2Base"/>
    <origin xyz="0.03698 0      0" rpy="0 0 0"/>
    <axis xyz="0 0 1"/>
    <limit lower="0" upper="0" effort="0" velocity="0"/>
  </joint>
  <joint name="Prism2MidSlider_joint" type="prismatic">
    <parent link="Prism2Base"/>
    <child link="Prism2MidSlider"/>
    <origin xyz="0.00924 0      0" rpy="0 0 0"/>
    <axis xyz="1 0 0"/>
    <limit lower="-0.019999999552965164" upper="0.019999999552965164" effort="0.0" velocity="0.0"/>
  </joint>
  <joint name="HandLink_joint" type="fixed">
    <parent link="Prism2MidSlider"/>
    <child link="HandLink"/>
    <origin xyz="0      0      0.01202" rpy="0 0 0"/>
    <axis xyz="0 0 1"/>
    <limit lower="0" upper="0" effort="0" velocity="0"/>
  </joint>
  <joint name="Act3_joint" type="fixed">
    <parent link="Wristlink2"/>
    <child link="Act3"/>
    <origin xyz="0     0    -0.003" rpy="0 0 0"/>
    <axis xyz="0 0 1"/>
    <limit lower="0" upper="0" effort="0" velocity="0"/>
  </joint>
  <link name="BaseLink">
    <inertial>
      <mass value="1.0"/>
      <origin xyz="0 0 0" rpy="0 0 0"/>
      <inertia ixx="1.0" ixy="0.0" ixz="0.0" iyy="1.0" iyz="0.0" izz="1.0"/>
    </inertial>
    <visual name="VIS_BaseLink">
      <origin xyz="0 0 0" rpy="0 0 0"/>
      <geometry>
        <mesh filename="package://rehab/models/RehabilitationDeviceForearmHand/ForearmRehab/meshes/visual/VIS_BaseLink.dae" scale="1.0 1.0 1.0"/>
      </geometry>
    </visual>
  </link>
  <link name="ElbowWristLink">
    <inertial>
      <mass value="1.0"/>
      <origin xyz="0 0 0" rpy="0 0 0"/>
      <inertia ixx="1.0" ixy="0.0" ixz="0.0" iyy="1.0" iyz="0.0" izz="1.0"/>
    </inertial>
    <visual name="VIS_ElbowWristLink">
      <origin xyz="0 0 0" rpy="0 0 0"/>
      <geometry>
        <mesh filename="package://rehab/models/RehabilitationDeviceForearmHand/ForearmRehab/meshes/visual/VIS_ElbowWristLink.dae" scale="1.0 1.0 1.0"/>
      </geometry>
    </visual>
  </link>
  <link name="Act1">
    <inertial>
      <mass value="1.0"/>
      <origin xyz="0 0 0" rpy="0 0 0"/>
      <inertia ixx="1.0" ixy="0.0" ixz="0.0" iyy="1.0" iyz="0.0" izz="1.0"/>
    </inertial>
    <visual name="VIS_Act1">
      <origin xyz="0 0 0" rpy="0 0 0"/>
      <geometry>
        <mesh filename="package://rehab/models/RehabilitationDeviceForearmHand/ForearmRehab/meshes/visual/VIS_Act1.dae" scale="1.4840679168701172 1.4840679168701172 1.4840679168701172"/>
      </geometry>
    </visual>
  </link>
  <link name="Prism1Base">
    <inertial>
      <mass value="1.0"/>
      <origin xyz="0 0 0" rpy="0 0 0"/>
      <inertia ixx="1.0" ixy="0.0" ixz="0.0" iyy="1.0" iyz="0.0" izz="1.0"/>
    </inertial>
    <visual name="VIS_Prism1Base">
      <origin xyz="0 0 0" rpy="0 0 0"/>
      <geometry>
        <mesh filename="package://rehab/models/RehabilitationDeviceForearmHand/ForearmRehab/meshes/visual/VIS_Prism1Base.dae" scale="1.0 1.0 1.0"/>
      </geometry>
    </visual>
  </link>
  <link name="Prism1MidSlider">
    <inertial>
      <mass value="1.0"/>
      <origin xyz="0 0 0" rpy="0 0 0"/>
      <inertia ixx="1.0" ixy="0.0" ixz="0.0" iyy="1.0" iyz="0.0" izz="1.0"/>
    </inertial>
    <visual name="VIS_Prism1MidSlider">
      <origin xyz="0 0 0" rpy="0 0 0"/>
      <geometry>
        <mesh filename="package://rehab/models/RehabilitationDeviceForearmHand/ForearmRehab/meshes/visual/VIS_Prism1MidSlider.dae" scale="1.0 1.0 1.0"/>
      </geometry>
    </visual>
  </link>
  <link name="WristSlider1">
    <inertial>
      <mass value="1.0"/>
      <origin xyz="0 0 0" rpy="0 0 0"/>
      <inertia ixx="1.0" ixy="0.0" ixz="0.0" iyy="1.0" iyz="0.0" izz="1.0"/>
    </inertial>
    <visual name="VIS_WristSlider1">
      <origin xyz="0 0 0" rpy="0 0 0"/>
      <geometry>
        <mesh filename="package://rehab/models/RehabilitationDeviceForearmHand/ForearmRehab/meshes/visual/VIS_WristSlider1.dae" scale="1.0 1.0 1.0"/>
      </geometry>
    </visual>
  </link>
  <link name="WristSlider2">
    <inertial>
      <mass value="1.0"/>
      <origin xyz="0 0 0" rpy="0 0 0"/>
      <inertia ixx="1.0" ixy="0.0" ixz="0.0" iyy="1.0" iyz="0.0" izz="1.0"/>
    </inertial>
    <visual name="VIS_WristSlider2">
      <origin xyz="0 0 0" rpy="0 0 0"/>
      <geometry>
        <mesh filename="package://rehab/models/RehabilitationDeviceForearmHand/ForearmRehab/meshes/visual/VIS_WristSlider2.dae" scale="1.0 1.0 1.0"/>
      </geometry>
    </visual>
  </link>
  <link name="Act2">
    <inertial>
      <mass value="1.0"/>
      <origin xyz="0 0 0" rpy="0 0 0"/>
      <inertia ixx="1.0" ixy="0.0" ixz="0.0" iyy="1.0" iyz="0.0" izz="1.0"/>
    </inertial>
    <visual name="VIS_Act2">
      <origin xyz="0 0 0" rpy="0 0 0"/>
      <geometry>
        <mesh filename="package://rehab/models/RehabilitationDeviceForearmHand/ForearmRehab/meshes/visual/VIS_Act2.dae" scale="1.0 1.0 1.0"/>
      </geometry>
    </visual>
  </link>
  <link name="WristLink1">
    <inertial>
      <mass value="1.0"/>
      <origin xyz="0 0 0" rpy="0 0 0"/>
      <inertia ixx="1.0" ixy="0.0" ixz="0.0" iyy="1.0" iyz="0.0" izz="1.0"/>
    </inertial>
    <visual name="VIS_WristLink1">
      <origin xyz="0 0 0" rpy="0 0 0"/>
      <geometry>
        <mesh filename="package://rehab/models/RehabilitationDeviceForearmHand/ForearmRehab/meshes/visual/VIS_WristLink1.dae" scale="1.0 1.0 1.0"/>
      </geometry>
    </visual>
  </link>
  <link name="WristRail1">
    <inertial>
      <mass value="1.0"/>
      <origin xyz="0 0 0" rpy="0 0 0"/>
      <inertia ixx="1.0" ixy="0.0" ixz="0.0" iyy="1.0" iyz="0.0" izz="1.0"/>
    </inertial>
    <visual name="VIS_WristRail1">
      <origin xyz="0 0 0" rpy="0 0 0"/>
      <geometry>
        <mesh filename="package://rehab/models/RehabilitationDeviceForearmHand/ForearmRehab/meshes/visual/VIS_WristRail1.dae" scale="0.9575729966163635 0.9575729966163635 0.9575729966163635"/>
      </geometry>
    </visual>
  </link>
  <link name="WristRail2">
    <inertial>
      <mass value="1.0"/>
      <origin xyz="0 0 0" rpy="0 0 0"/>
      <inertia ixx="1.0" ixy="0.0" ixz="0.0" iyy="1.0" iyz="0.0" izz="1.0"/>
    </inertial>
    <visual name="VIS_WristRail2">
      <origin xyz="0 0 0" rpy="0 0 0"/>
      <geometry>
        <mesh filename="package://rehab/models/RehabilitationDeviceForearmHand/ForearmRehab/meshes/visual/VIS_WristRail2.dae" scale="0.9575730562210083 0.9575730562210083 0.9575730562210083"/>
      </geometry>
    </visual>
  </link>
  <link name="ForearmInterface">
    <inertial>
      <mass value="1.0"/>
      <origin xyz="0 0 0" rpy="0 0 0"/>
      <inertia ixx="1.0" ixy="0.0" ixz="0.0" iyy="1.0" iyz="0.0" izz="1.0"/>
    </inertial>
    <visual name="VIS_ForearmInterface">
      <origin xyz="0 0 0" rpy="0 0 0"/>
      <geometry>
        <mesh filename="package://rehab/models/RehabilitationDeviceForearmHand/ForearmRehab/meshes/visual/VIS_ForearmInterface.dae" scale="1.0 1.0 1.0"/>
      </geometry>
    </visual>
  </link>
  <link name="Wristlink2">
    <inertial>
      <mass value="1.0"/>
      <origin xyz="0 0 0" rpy="0 0 0"/>
      <inertia ixx="1.0" ixy="0.0" ixz="0.0" iyy="1.0" iyz="0.0" izz="1.0"/>
    </inertial>
    <visual name="VIS_WristLink2">
      <origin xyz="0 0 0" rpy="0 0 0"/>
      <geometry>
        <mesh filename="package://rehab/models/RehabilitationDeviceForearmHand/ForearmRehab/meshes/visual/VIS_WristLink2.dae" scale="1.0 1.0 1.0"/>
      </geometry>
    </visual>
  </link>
  <link name="ElasticHingePart1">
    <inertial>
      <mass value="1.0"/>
      <origin xyz="0 0 0" rpy="0 0 0"/>
      <inertia ixx="1.0" ixy="0.0" ixz="0.0" iyy="1.0" iyz="0.0" izz="1.0"/>
    </inertial>
    <visual name="VIS_ElasticHingePart1">
      <origin xyz="0 0 0" rpy="0 0 0"/>
      <geometry>
        <mesh filename="package://rehab/models/RehabilitationDeviceForearmHand/ForearmRehab/meshes/visual/VIS_ElasticHingePart1.dae" scale="1.0 1.0 1.0"/>
      </geometry>
    </visual>
  </link>
  <link name="Act4">
    <inertial>
      <mass value="1.0"/>
      <origin xyz="0 0 0" rpy="0 0 0"/>
      <inertia ixx="1.0" ixy="0.0" ixz="0.0" iyy="1.0" iyz="0.0" izz="1.0"/>
    </inertial>
    <visual name="VIS_Act4">
      <origin xyz="0 0 0" rpy="0 0 0"/>
      <geometry>
        <mesh filename="package://rehab/models/RehabilitationDeviceForearmHand/ForearmRehab/meshes/visual/VIS_Act4.dae" scale="1.04426908493042 1.04426908493042 1.04426908493042"/>
      </geometry>
    </visual>
  </link>
  <link name="ElasticHingePart2">
    <inertial>
      <mass value="1.0"/>
      <origin xyz="0 0 0" rpy="0 0 0"/>
      <inertia ixx="1.0" ixy="0.0" ixz="0.0" iyy="1.0" iyz="0.0" izz="1.0"/>
    </inertial>
    <visual name="VIS_ElasticHingePart2">
      <origin xyz="0 0 0" rpy="0 0 0"/>
      <geometry>
        <mesh filename="package://rehab/models/RehabilitationDeviceForearmHand/ForearmRehab/meshes/visual/VIS_ElasticHingePart2.dae" scale="1.0 1.0 1.0"/>
      </geometry>
    </visual>
  </link>
  <link name="Prism2Base">
    <inertial>
      <mass value="1.0"/>
      <origin xyz="0 0 0" rpy="0 0 0"/>
      <inertia ixx="1.0" ixy="0.0" ixz="0.0" iyy="1.0" iyz="0.0" izz="1.0"/>
    </inertial>
    <visual name="VIS_Prism2Base">
      <origin xyz="0 0 0" rpy="0 0 0"/>
      <geometry>
        <mesh filename="package://rehab/models/RehabilitationDeviceForearmHand/ForearmRehab/meshes/visual/VIS_Prism2Base.dae" scale="1.0 1.0 1.0"/>
      </geometry>
    </visual>
  </link>
  <link name="Prism2MidSlider">
    <inertial>
      <mass value="1.0"/>
      <origin xyz="0 0 0" rpy="0 0 0"/>
      <inertia ixx="1.0" ixy="0.0" ixz="0.0" iyy="1.0" iyz="0.0" izz="1.0"/>
    </inertial>
    <visual name="VIS_Prism2MidSlider">
      <origin xyz="0 0 0" rpy="0 0 0"/>
      <geometry>
        <mesh filename="package://rehab/models/RehabilitationDeviceForearmHand/ForearmRehab/meshes/visual/VIS_Prism2MidSlider.dae" scale="1.0 1.0 1.0"/>
      </geometry>
    </visual>
  </link>
  <link name="HandLink">
    <inertial>
      <mass value="1.0"/>
      <origin xyz="0 0 0" rpy="0 0 0"/>
      <inertia ixx="1.0" ixy="0.0" ixz="0.0" iyy="1.0" iyz="0.0" izz="1.0"/>
    </inertial>
    <visual name="VIS_HandLink">
      <origin xyz="0 0 0" rpy="0 0 0"/>
      <geometry>
        <mesh filename="package://rehab/models/RehabilitationDeviceForearmHand/ForearmRehab/meshes/visual/VIS_HandLink.dae" scale="1.0 1.0 1.0"/>
      </geometry>
    </visual>
  </link>
  <link name="Act3">
    <inertial>
      <mass value="1.0"/>
      <origin xyz="0 0 0" rpy="0 0 0"/>
      <inertia ixx="1.0" ixy="0.0" ixz="0.0" iyy="1.0" iyz="0.0" izz="1.0"/>
    </inertial>
    <visual name="VIS_Act3">
      <origin xyz="0 0 0" rpy="0 0 0"/>
      <geometry>
        <mesh filename="package://rehab/models/RehabilitationDeviceForearmHand/ForearmRehab/meshes/visual/VIS_Act3.dae" scale="1.0 1.0 1.0"/>
      </geometry>
    </visual>
  </link>
</robot>
