<?xml version="1.0" encoding="utf-8"?>
<!-- =================================================================================== -->
<!-- |    This document was autogenerated by xacro from rehab.urdf.xacro               | -->
<!-- |    EDITING THIS FILE BY HAND IS NOT RECOMMENDED                                 | -->
<!-- =================================================================================== -->
<robot name="rehab">
  <!-- Material colors -->
  <material name="blue">
    <color rgba="0 0 0.8 1"/>
  </material>
  <material name="black">
    <color rgba="0 0 0 1"/>
  </material>
  <material name="white">
    <color rgba="1 1 1 1"/>
  </material>
  <!-- Shoulder links and joints -->
  <link name="base_link">
    <!-- <visual> -->
    <!-- <geometry> -->
    <!-- </geometry> -->
    <!-- </visual> -->
  </link>
  <link name="shoulder1">
    <!-- <visual> -->
    <!-- <geometry> -->
    <!-- </geometry> -->
    <!-- </visual> -->
  </link>
  <link name="shoulder2">
    <!-- <visual> -->
    <!-- <geometry> -->
    <!-- </geometry> -->
    <!-- </visual> -->
  </link>
  <link name="shoulder3">
    <!-- <visual> -->
    <!-- <geometry> -->
    <!-- </geometry> -->
    <!-- </visual> -->
  </link>
  <link name="shoulder4">
    <!-- <visual> -->
    <!-- <geometry> -->
    <!-- </geometry> -->
    <!-- </visual> -->
  </link>
  <link name="shoulder5">
    <!-- <visual> -->
    <!-- <geometry> -->
    <!-- </geometry> -->
    <!-- </visual> -->
  </link>
  <link name="shoulder6">
    <!-- <visual> -->
    <!-- <geometry> -->
    <!-- </geometry> -->
    <!-- </visual> -->
  </link>
  <link name="shoulder7">
    <!-- <visual> -->
    <!-- <geometry> -->
    <!-- </geometry> -->
    <!-- </visual> -->
  </link>
  <link name="shoulder8">
    <!-- <visual> -->
    <!-- <geometry> -->
    <!-- </geometry> -->
    <!-- </visual> -->
  </link>
  <link name="shoulder9">
    <!-- <visual> -->
    <!-- <geometry> -->
    <!-- </geometry> -->
    <!-- </visual> -->
  </link>
  <link name="shoulder10">
    <!-- <visual> -->
    <!-- <geometry> -->
    <!-- </geometry> -->
    <!-- </visual> -->
  </link>
  <link name="shoulder11">
    <!-- <visual> -->
    <!-- <geometry> -->
    <!-- </geometry> -->
    <!-- </visual> -->
  </link>
  <joint name="base_to_shoulder1" type="fixed">
    <parent link="base_link"/>
    <child link="shoulder1"/>
    <origin rpy="0 0 0" xyz="0 0 0"/>
  </joint>
  <joint name="sh1_sh2" type="prismatic">
    <parent link="shoulder1"/>
    <child link="shoulder2"/>
    <origin rpy="0 0 0" xyz="0 0 0"/>
    <limit effort="300.0" lower="-0.5" upper="0.5" velocity="5.0"/>
  </joint>
  <joint name="sh2_sh3" type="prismatic">
    <parent link="shoulder2"/>
    <child link="shoulder3"/>
    <origin rpy="0 0 0" xyz="0 0 0"/>
    <limit effort="300.0" lower="-0.5" upper="0.5" velocity="5.0"/>
  </joint>
  <joint name="sh3_sh4" type="fixed">
    <parent link="shoulder3"/>
    <child link="shoulder4"/>
    <origin rpy="0 0 0" xyz="0 0 0"/>
    <limit effort="300.0" lower="-0.5" upper="0.5" velocity="5.0"/>
  </joint>
  <joint name="sh4_sh5" type="continuous">
    <parent link="shoulder4"/>
    <child link="shoulder5"/>
    <origin rpy="0 0 0" xyz="0 0 0"/>
    <limit effort="300.0" lower="-0.5" upper="0.5" velocity="5.0"/>
  </joint>
  <joint name="sh5_sh6" type="fixed">
    <parent link="shoulder5"/>
    <child link="shoulder6"/>
    <origin rpy="0 0 0" xyz="0 0 0"/>
    <limit effort="300.0" lower="-0.5" upper="0.5" velocity="5.0"/>
  </joint>
  <joint name="sh6_sh7" type="continuous">
    <parent link="shoulder6"/>
    <child link="shoulder7"/>
    <origin rpy="0 0 0" xyz="0 0 0"/>
    <limit effort="300.0" lower="-0.5" upper="0.5" velocity="5.0"/>
  </joint>
  <joint name="sh7_sh8" type="fixed">
    <parent link="shoulder7"/>
    <child link="shoulder8"/>
    <origin rpy="0 0 0" xyz="0 0 0"/>
    <limit effort="300.0" lower="-0.5" upper="0.5" velocity="5.0"/>
  </joint>
  <joint name="sh8_sh9" type="prismatic">
    <parent link="shoulder8"/>
    <child link="shoulder9"/>
    <origin rpy="0 0 0" xyz="0 0 0"/>
    <limit effort="300.0" lower="-0.5" upper="0.5" velocity="5.0"/>
  </joint>
  <joint name="sh9_sh10" type="continuous">
    <parent link="shoulder9"/>
    <child link="shoulder10"/>
    <origin rpy="0 0 0" xyz="0 0 0"/>
    <limit effort="300.0" lower="-0.5" upper="0.5" velocity="5.0"/>
  </joint>
  <joint name="sh10_sh11" type="fixed">
    <parent link="shoulder10"/>
    <child link="shoulder11"/>
    <origin rpy="0 0 0" xyz="0 0 0"/>
    <limit effort="300.0" lower="-0.5" upper="0.5" velocity="5.0"/>
  </joint>
  <!-- Elbow links and joints -->
  <link name="elbow1">
    <!-- <visual> -->
    <!-- <geometry> -->
    <!-- </geometry> -->
    <!-- </visual> -->
  </link>
  <link name="elbow2">
    <!-- <visual> -->
    <!-- <geometry> -->
    <!-- </geometry> -->
    <!-- </visual> -->
  </link>
  <link name="elbow3">
    <!-- <visual> -->
    <!-- <geometry> -->
    <!-- </geometry> -->
    <!-- </visual> -->
  </link>
  <link name="elbow4">
    <!-- <visual> -->
    <!-- <geometry> -->
    <!-- </geometry> -->
    <!-- </visual> -->
  </link>
  <link name="elbow5">
    <!-- <visual> -->
    <!-- <geometry> -->
    <!-- </geometry> -->
    <!-- </visual> -->
  </link>
  <joint name="sh11_el1" type="continuous">
    <parent link="shoulder11"/>
    <child link="elbow1"/>
    <origin rpy="0 0 0" xyz="0 0 0"/>
  </joint>
  <joint name="el1_el2" type="fixed">
    <parent link="elbow1"/>
    <child link="elbow2"/>
    <origin rpy="0 0 0" xyz="0 0 0"/>
    <limit effort="300.0" lower="-0.5" upper="0.5" velocity="5.0"/>
  </joint>
  <joint name="el2_el3" type="prismatic">
    <parent link="elbow2"/>
    <child link="elbow3"/>
    <origin rpy="0 0 0" xyz="0 0 0"/>
    <limit effort="300.0" lower="-0.5" upper="0.5" velocity="5.0"/>
  </joint>
  <joint name="el3_el4" type="continuous">
    <parent link="elbow3"/>
    <child link="elbow4"/>
    <origin rpy="0 0 0" xyz="0 0 0"/>
    <limit effort="300.0" lower="-0.5" upper="0.5" velocity="5.0"/>
  </joint>
  <joint name="el4_el5" type="fixed">
    <parent link="elbow4"/>
    <child link="elbow5"/>
    <origin rpy="0 0 0" xyz="0 0 0"/>
    <limit effort="300.0" lower="-0.5" upper="0.5" velocity="5.0"/>
  </joint>
  <!-- Wrist and hand links and joints -->
  <link name="wrist1">
    <!-- <visual> -->
    <!-- <geometry> -->
    <!-- </geometry> -->
    <!-- </visual> -->
  </link>
  <link name="wrist2">
    <!-- <visual> -->
    <!-- <geometry> -->
    <!-- </geometry> -->
    <!-- </visual> -->
  </link>
  <link name="wrist3">
    <!-- <visual> -->
    <!-- <geometry> -->
    <!-- </geometry> -->
    <!-- </visual> -->
  </link>
  <link name="wrist4">
    <!-- <visual> -->
    <!-- <geometry> -->
    <!-- </geometry> -->
    <!-- </visual> -->
  </link>
  <link name="wrist5">
    <!-- <visual> -->
    <!-- <geometry> -->
    <!-- </geometry> -->
    <!-- </visual> -->
  </link>
  <link name="wrist6">
    <!-- <visual> -->
    <!-- <geometry> -->
    <!-- </geometry> -->
    <!-- </visual> -->
  </link>
  <joint name="el5_wr1" type="continuous">
    <parent link="elbow5"/>
    <child link="wrist1"/>
    <origin rpy="0 0 0" xyz="0 0 0"/>
  </joint>
  <joint name="wr1_wr2" type="fixed">
    <parent link="wrist1"/>
    <child link="wrist2"/>
    <origin rpy="0 0 0" xyz="0 0 0"/>
    <limit effort="300.0" lower="-0.5" upper="0.5" velocity="5.0"/>
  </joint>
  <joint name="wr2_wr3" type="continuous">
    <parent link="wrist2"/>
    <child link="wrist3"/>
    <origin rpy="0 0 0" xyz="0 0 0"/>
    <limit effort="300.0" lower="-0.5" upper="0.5" velocity="5.0"/>
  </joint>
  <joint name="wr3_wr4_rotx" type="revolute">
    <parent link="wrist3"/>
    <child link="wrist4"/>
    <origin rpy="0 0 0" xyz="0 0 0"/>
    <limit effort="300.0" lower="-0.5" upper="0.5" velocity="5.0"/>
  </joint>
  <joint name="wr3_wr4_roty" type="revolute">
    <parent link="wrist3"/>
    <child link="wrist4"/>
    <origin rpy="0 0 0" xyz="0 0 0"/>
    <limit effort="300.0" lower="-0.5" upper="0.5" velocity="5.0"/>
  </joint>
  <joint name="wr3_wr4_rotz" type="revolute">
    <parent link="wrist3"/>
    <child link="wrist4"/>
    <origin rpy="0 0 0" xyz="0 0 0"/>
    <limit effort="300.0" lower="-0.5" upper="0.5" velocity="5.0"/>
  </joint>
  <joint name="wr4_wr5" type="prismatic">
    <parent link="wrist4"/>
    <child link="wrist5"/>
    <origin rpy="0 0 0" xyz="0 0 0"/>
    <limit effort="300.0" lower="-0.5" upper="0.5" velocity="5.0"/>
  </joint>
  <joint name="wr5_wr6" type="continuous">
    <parent link="wrist5"/>
    <child link="wrist6"/>
    <origin rpy="0 0 0" xyz="0 0 0"/>
    <limit effort="300.0" lower="-0.5" upper="0.5" velocity="5.0"/>
  </joint>
</robot>

